Workbook

Sheet Instrucciones
A2: Descargar de Jira BUGS del filtro de Jira y pegarlos en la pestaña Jira BUGS
A3: C360 Auditoria BUGS OPERACIONAL

Sheet Jira BUGS
A1: Key | B1: Summary | C1: Persona asignada | D1: Prioridad | E1: Estado | F1: Actualizada | G1: Fecha Vencimiento | H1: Creada | I1: Fecha Fin Real | J1: Fecha Inicio Real | K1: Opción 2 | L1: Dias | M1: Opción 3 | N1: Días Resolucion | O1: Mes bug creado | P1: Mes creación | Q1: Año creación | R1: Fecha creación | S1: Mes bug resolucion | T1: Mes resolución | U1: Año resolución | V1: Fecha resolución | W1: Dias abiertos | X1: SLA | Y1: Cumple SLA
A2: ESPC360-21480 | B2: C360_Operacional_Sprint 212_Expres | C2: ERNESTO Gimeno Valiente | D2: Medium | E2: CERRADO ITSM | F2: 45959.615 | H2: 45946.562 | I2: 45959 | J2: 45946 | K2: C360_Operacional_Sprint 212 Expres | L2: 12 | M2: OPERACIONAL | N2: Resolved | O2: =MONTH(H2) -> 10 | P2: =IF(O2=1,"enero",IF(O2=2,"febrero",IF(O2=3,"marzo",IF(O2=4,"abril",IF(O2=5,"mayo",IF(O2=6,"junio",IF(O2=7,"julio",IF(O2=8,"agosto",IF(O2=9,"septiembre",IF(O2=10,"octubre",IF(O2=11,"noviembre",IF(O2=12,"diciembre","REVISAR")))))))))))) -> octubre | Q2: =YEAR(H2) -> 2025 | R2: =CONCATENATE(P2,"-",Q2) -> octubre-2025 | S2: =MONTH(I2) -> 10 | T2: =IF(S2=1,"enero",IF(S2=2,"febrero",IF(S2=3,"marzo",IF(S2=4,"abril",IF(S2=5,"mayo",IF(S2=6,"junio",IF(S2=7,"julio",IF(S2=8,"agosto",IF(S2=9,"septiembre",IF(S2=10,"octubre",IF(S2=11,"noviembre",IF(S2=12,"diciembre","REVISAR")))))))))))) -> octubre | U2: =YEAR(I2) -> 2025 | V2: =CONCATENATE(T2,"-",U2) -> octubre-2025 | W2: =IFERROR(_xlfn.DAYS('Jira BUGS'!I2,'Jira BUGS'!H2),0) -> 13 | X2: =VLOOKUP(D2,SLAs!A:B,2,0) -> 21 | Y2: =IF(N2>=X2,"NO CUMPLE","CUMPLE") -> NO CUMPLE
A3: ESPC360-21196 | B3: C360_Operacional_Sprint 212 | D3: Medium | E3: CERRADO ITSM | F3: 45959.614 | H3: 45932.507 | I3: 45959 | J3: 45950 | K3: C360_Operacional_Sprint 212 | L3: 26 | M3: OPERACIONAL | N3: Resolved | O3: =MONTH(H3) -> 10 | P3: =IF(O3=1,"enero",IF(O3=2,"febrero",IF(O3=3,"marzo",IF(O3=4,"abril",IF(O3=5,"mayo",IF(O3=6,"junio",IF(O3=7,"julio",IF(O3=8,"agosto",IF(O3=9,"septiembre",IF(O3=10,"octubre",IF(O3=11,"noviembre",IF(O3=12,"diciembre","REVISAR")))))))))))) -> octubre | Q3: =YEAR(H3) -> 2025 | R3: =CONCATENATE(P3,"-",Q3) -> octubre-2025 | S3: =MONTH(I3) -> 10 | T3: =IF(S3=1,"enero",IF(S3=2,"febrero",IF(S3=3,"marzo",IF(S3=4,"abril",IF(S3=5,"mayo",IF(S3=6,"junio",IF(S3=7,"julio",IF(S3=8,"agosto",IF(S3=9,"septiembre",IF(S3=10,"octubre",IF(S3=11,"noviembre",IF(S3=12,"diciembre","REVISAR")))))))))))) -> octubre | U3: =YEAR(I3) -> 2025 | V3: =CONCATENATE(T3,"-",U3) -> octubre-2025 | W3: =IFERROR(_xlfn.DAYS('Jira BUGS'!I3,'Jira BUGS'!H3),0) -> 27 | X3: =VLOOKUP(D3,SLAs!A:B,2,0) -> 21 | Y3: =IF(N3>=X3,"NO CUMPLE","CUMPLE") -> NO CUMPLE
A4: ESPC360-20940 | B4: C360_Operacional_Sprint 211 | C4: ERNESTO Gimeno Valiente | D4: Medium | E4: CERRADO ITSM | F4: 45959.612 | H4: 45918.513 | I4: 45951 | J4: 45951 | K4: C360_Operacional_Sprint 211 | L4: 40 | M4: OPERACIONAL | N4: Resolved | O4: =MONTH(H4) -> 9 | P4: =IF(O4=1,"enero",IF(O4=2,"febrero",IF(O4=3,"marzo",IF(O4=4,"abril",IF(O4=5,"mayo",IF(O4=6,"junio",IF(O4=7,"julio",IF(O4=8,"agosto",IF(O4=9,"septiembre",IF(O4=10,"octubre",IF(O4=11,"noviembre",IF(O4=12,"diciembre","REVISAR")))))))))))) -> septiembre | Q4: =YEAR(H4) -> 2025 | R4: =CONCATENATE(P4,"-",Q4) -> septiembre-2025 | S4: =MONTH(I4) -> 10 | T4: =IF(S4=1,"enero",IF(S4=2,"febrero",IF(S4=3,"marzo",IF(S4=4,"abril",IF(S4=5,"mayo",IF(S4=6,"junio",IF(S4=7,"julio",IF(S4=8,"agosto",IF(S4=9,"septiembre",IF(S4=10,"octubre",IF(S4=11,"noviembre",IF(S4=12,"diciembre","REVISAR")))))))))))) -> octubre | U4: =YEAR(I4) -> 2025 | V4: =CONCATENATE(T4,"-",U4) -> octubre-2025 | W4: =IFERROR(_xlfn.DAYS('Jira BUGS'!I4,'Jira BUGS'!H4),0) -> 33 | X4: =VLOOKUP(D4,SLAs!A:B,2,0) -> 21 | Y4: =IF(N4>=X4,"NO CUMPLE","CUMPLE") -> NO CUMPLE
A5: ESPC360-20658 | B5: C360_Operacional_Sprint 210 | C5: ERNESTO Gimeno Valiente | D5: Medium | E5: CERRADO ITSM | F5: 45932.444 | H5: 45904.525 | I5: 45932 | J5: 45918 | K5: C360_Operacional_Sprint 210 | L5: 27 | M5: OPERACIONAL | N5: Resolved | O5: =MONTH(H5) -> 9 | P5: =IF(O5=1,"enero",IF(O5=2,"febrero",IF(O5=3,"marzo",IF(O5=4,"abril",IF(O5=5,"mayo",IF(O5=6,"junio",IF(O5=7,"julio",IF(O5=8,"agosto",IF(O5=9,"septiembre",IF(O5=10,"octubre",IF(O5=11,"noviembre",IF(O5=12,"diciembre","REVISAR")))))))))))) -> septiembre | Q5: =YEAR(H5) -> 2025 | R5: =CONCATENATE(P5,"-",Q5) -> septiembre-2025 | S5: =MONTH(I5) -> 10 | T5: =IF(S5=1,"enero",IF(S5=2,"febrero",IF(S5=3,"marzo",IF(S5=4,"abril",IF(S5=5,"mayo",IF(S5=6,"junio",IF(S5=7,"julio",IF(S5=8,"agosto",IF(S5=9,"septiembre",IF(S5=10,"octubre",IF(S5=11,"noviembre",IF(S5=12,"diciembre","REVISAR")))))))))))) -> octubre | U5: =YEAR(I5) -> 2025 | V5: =CONCATENATE(T5,"-",U5) -> octubre-2025 | W5: =IFERROR(_xlfn.DAYS('Jira BUGS'!I5,'Jira BUGS'!H5),0) -> 28 | X5: =VLOOKUP(D5,SLAs!A:B,2,0) -> 21 | Y5: =IF(N5>=X5,"NO CUMPLE","CUMPLE") -> NO CUMPLE
A6: ESPC360-20902 | B6: C360_Operacional_HotFix_Valores | C6: ERNESTO Gimeno Valiente | D6: Medium | E6: CERRADO ITSM | F6: 45926.484 | H6: 45915.68 | I6: 45926 | J6: 45917 | L6: 10 | M6: OPERACIONAL | N6: Resolved | O6: =MONTH(H6) -> 9 | P6: =IF(O6=1,"enero",IF(O6=2,"febrero",IF(O6=3,"marzo",IF(O6=4,"abril",IF(O6=5,"mayo",IF(O6=6,"junio",IF(O6=7,"julio",IF(O6=8,"agosto",IF(O6=9,"septiembre",IF(O6=10,"octubre",IF(O6=11,"noviembre",IF(O6=12,"diciembre","REVISAR")))))))))))) -> septiembre | Q6: =YEAR(H6) -> 2025 | R6: =CONCATENATE(P6,"-",Q6) -> septiembre-2025 | S6: =MONTH(I6) -> 9 | T6: =IF(S6=1,"enero",IF(S6=2,"febrero",IF(S6=3,"marzo",IF(S6=4,"abril",IF(S6=5,"mayo",IF(S6=6,"junio",IF(S6=7,"julio",IF(S6=8,"agosto",IF(S6=9,"septiembre",IF(S6=10,"octubre",IF(S6=11,"noviembre",IF(S6=12,"diciembre","REVISAR")))))))))))) -> septiembre | U6: =YEAR(I6) -> 2025 | V6: =CONCATENATE(T6,"-",U6) -> septiembre-2025 | W6: =IFERROR(_xlfn.DAYS('Jira BUGS'!I6,'Jira BUGS'!H6),0) -> 11 | X6: =VLOOKUP(D6,SLAs!A:B,2,0) -> 21 | Y6: =IF(N6>=X6,"NO CUMPLE","CUMPLE") -> NO CUMPLE
A7: ESPC360-20479 | B7: C360_Operacional_Sprint 209 | C7: ERNESTO Gimeno Valiente | D7: Medium | E7: CERRADO ITSM | F7: 45926.483 | H7: 45894.397 | I7: 45926 | J7: 45912 | K7: C360_Operacional_Sprint 209 | L7: 31 | M7: OPERACIONAL | N7: Resolved | O7: =MONTH(H7) -> 8 | P7: =IF(O7=1,"enero",IF(O7=2,"febrero",IF(O7=3,"marzo",IF(O7=4,"abril",IF(O7=5,"mayo",IF(O7=6,"junio",IF(O7=7,"julio",IF(O7=8,"agosto",IF(O7=9,"septiembre",IF(O7=10,"octubre",IF(O7=11,"noviembre",IF(O7=12,"diciembre","REVISAR")))))))))))) -> agosto | Q7: =YEAR(H7) -> 2025 | R7: =CONCATENATE(P7,"-",Q7) -> agosto-2025 | S7: =MONTH(I7) -> 9 | T7: =IF(S7=1,"enero",IF(S7=2,"febrero",IF(S7=3,"marzo",IF(S7=4,"abril",IF(S7=5,"mayo",IF(S7=6,"junio",IF(S7=7,"julio",IF(S7=8,"agosto",IF(S7=9,"septiembre",IF(S7=10,"octubre",IF(S7=11,"noviembre",IF(S7=12,"diciembre","REVISAR")))))))))))) -> septiembre | U7: =YEAR(I7) -> 2025 | V7: =CONCATENATE(T7,"-",U7) -> septiembre-2025 | W7: =IFERROR(_xlfn.DAYS('Jira BUGS'!I7,'Jira BUGS'!H7),0) -> 32 | X7: =VLOOKUP(D7,SLAs!A:B,2,0) -> 21 | Y7: =IF(N7>=X7,"NO CUMPLE","CUMPLE") -> NO CUMPLE
A8: ESPC360-20508 | B8: [CM] Modificación incrementales hismo | C8: GONZALO GARCIA MORENO | D8: Medium | E8: CERRADO ITSM | F8: 45924.657 | H8: 45895.42 | I8: 45924 | J8: 45901 | L8: 28 | M8: OPERACIONAL | N8: Resolved | O8: =MONTH(H8) -> 8 | P8: =IF(O8=1,"enero",IF(O8=2,"febrero",IF(O8=3,"marzo",IF(O8=4,"abril",IF(O8=5,"mayo",IF(O8=6,"junio",IF(O8=7,"julio",IF(O8=8,"agosto",IF(O8=9,"septiembre",IF(O8=10,"octubre",IF(O8=11,"noviembre",IF(O8=12,"diciembre","REVISAR")))))))))))) -> agosto | Q8: =YEAR(H8) -> 2025 | R8: =CONCATENATE(P8,"-",Q8) -> agosto-2025 | S8: =MONTH(I8) -> 9 | T8: =IF(S8=1,"enero",IF(S8=2,"febrero",IF(S8=3,"marzo",IF(S8=4,"abril",IF(S8=5,"mayo",IF(S8=6,"junio",IF(S8=7,"julio",IF(S8=8,"agosto",IF(S8=9,"septiembre",IF(S8=10,"octubre",IF(S8=11,"noviembre",IF(S8=12,"diciembre","REVISAR")))))))))))) -> septiembre | U8: =YEAR(I8) -> 2025 | V8: =CONCATENATE(T8,"-",U8) -> septiembre-2025 | W8: =IFERROR(_xlfn.DAYS('Jira BUGS'!I8,'Jira BUGS'!H8),0) -> 29 | X8: =VLOOKUP(D8,SLAs!A:B,2,0) -> 21 | Y8: =IF(N8>=X8,"NO CUMPLE","CUMPLE") -> NO CUMPLE
A9: ESPC360-19953 | B9: [CM] Modificación ingestas previas update-catalogo-productos y desplanificación jobs cloudera | C9: BORJA CORTIJO LAJARA | D9: Medium | E9: CERRADO ITSM | F9: 45904.519 | H9: 45862.504 | I9: 45904 | J9: 45862 | L9: 41 | M9: OPERACIONAL | N9: Resolved | O9: =MONTH(H9) -> 7 | P9: =IF(O9=1,"enero",IF(O9=2,"febrero",IF(O9=3,"marzo",IF(O9=4,"abril",IF(O9=5,"mayo",IF(O9=6,"junio",IF(O9=7,"julio",IF(O9=8,"agosto",IF(O9=9,"septiembre",IF(O9=10,"octubre",IF(O9=11,"noviembre",IF(O9=12,"diciembre","REVISAR")))))))))))) -> julio | Q9: =YEAR(H9) -> 2025 | R9: =CONCATENATE(P9,"-",Q9) -> julio-2025 | S9: =MONTH(I9) -> 9 | T9: =IF(S9=1,"enero",IF(S9=2,"febrero",IF(S9=3,"marzo",IF(S9=4,"abril",IF(S9=5,"mayo",IF(S9=6,"junio",IF(S9=7,"julio",IF(S9=8,"agosto",IF(S9=9,"septiembre",IF(S9=10,"octubre",IF(S9=11,"noviembre",IF(S9=12,"diciembre","REVISAR")))))))))))) -> septiembre | U9: =YEAR(I9) -> 2025 | V9: =CONCATENATE(T9,"-",U9) -> septiembre-2025 | W9: =IFERROR(_xlfn.DAYS('Jira BUGS'!I9,'Jira BUGS'!H9),0) -> 42 | X9: =VLOOKUP(D9,SLAs!A:B,2,0) -> 21 | Y9: =IF(N9>=X9,"NO CUMPLE","CUMPLE") -> NO CUMPLE
A10: ESPC360-20269 | B10: C360_Operacional_Sprint 208 | C10: ERNESTO Gimeno Valiente | D10: Medium | E10: CERRADO ITSM | F10: 45903.051 | H10: 45876.585 | I10: 45902 | J10: 45897 | K10: C360_Operacional_Sprint 208 | L10: 25 | M10: OPERACIONAL | N10: Resolved | O10: =MONTH(H10) -> 8 | P10: =IF(O10=1,"enero",IF(O10=2,"febrero",IF(O10=3,"marzo",IF(O10=4,"abril",IF(O10=5,"mayo",IF(O10=6,"junio",IF(O10=7,"julio",IF(O10=8,"agosto",IF(O10=9,"septiembre",IF(O10=10,"octubre",IF(O10=11,"noviembre",IF(O10=12,"diciembre","REVISAR")))))))))))) -> agosto | Q10: =YEAR(H10) -> 2025 | R10: =CONCATENATE(P10,"-",Q10) -> agosto-2025 | S10: =MONTH(I10) -> 9 | T10: =IF(S10=1,"enero",IF(S10=2,"febrero",IF(S10=3,"marzo",IF(S10=4,"abril",IF(S10=5,"mayo",IF(S10=6,"junio",IF(S10=7,"julio",IF(S10=8,"agosto",IF(S10=9,"septiembre",IF(S10=10,"octubre",IF(S10=11,"noviembre",IF(S10=12,"diciembre","REVISAR")))))))))))) -> septiembre | U10: =YEAR(I10) -> 2025 | V10: =CONCATENATE(T10,"-",U10) -> septiembre-2025 | W10: =IFERROR(_xlfn.DAYS('Jira BUGS'!I10,'Jira BUGS'!H10),0) -> 26 | X10: =VLOOKUP(D10,SLAs!A:B,2,0) -> 21 | Y10: =IF(N10>=X10,"NO CUMPLE","CUMPLE") -> NO CUMPLE
A11: ESPC360-19956 | B11: C360_Operacional_Sprint 207 | C11: ERNESTO Gimeno Valiente | D11: Medium | E11: CERRADO ITSM | F11: 45945.714 | H11: 45862.555 | I11: 45889 | J11: 45877 | K11: C360_Operacional_Sprint 207 | L11: 26 | M11: OPERACIONAL | N11: Resolved | O11: =MONTH(H11) -> 7 | P11: =IF(O11=1,"enero",IF(O11=2,"febrero",IF(O11=3,"marzo",IF(O11=4,"abril",IF(O11=5,"mayo",IF(O11=6,"junio",IF(O11=7,"julio",IF(O11=8,"agosto",IF(O11=9,"septiembre",IF(O11=10,"octubre",IF(O11=11,"noviembre",IF(O11=12,"diciembre","REVISAR")))))))))))) -> julio | Q11: =YEAR(H11) -> 2025 | R11: =CONCATENATE(P11,"-",Q11) -> julio-2025 | S11: =MONTH(I11) -> 8 | T11: =IF(S11=1,"enero",IF(S11=2,"febrero",IF(S11=3,"marzo",IF(S11=4,"abril",IF(S11=5,"mayo",IF(S11=6,"junio",IF(S11=7,"julio",IF(S11=8,"agosto",IF(S11=9,"septiembre",IF(S11=10,"octubre",IF(S11=11,"noviembre",IF(S11=12,"diciembre","REVISAR")))))))))))) -> agosto | U11: =YEAR(I11) -> 2025 | V11: =CONCATENATE(T11,"-",U11) -> agosto-2025 | W11: =IFERROR(_xlfn.DAYS('Jira BUGS'!I11,'Jira BUGS'!H11),0) -> 27 | X11: =VLOOKUP(D11,SLAs!A:B,2,0) -> 21 | Y11: =IF(N11>=X11,"NO CUMPLE","CUMPLE") -> NO CUMPLE
A12: ESPC360-20264 | B12: C360_Operacional_Sprint 207 - Exprés | C12: ERNESTO Gimeno Valiente | D12: Medium | E12: CERRADO ITSM | F12: 45882.62 | H12: 45876.579 | I12: 45882 | J12: 45876 | K12: C360_Operacional_Sprint 207 - Exprés | L12: 5 | M12: OPERACIONAL | N12: Resolved | O12: =MONTH(H12) -> 8 | P12: =IF(O12=1,"enero",IF(O12=2,"febrero",IF(O12=3,"marzo",IF(O12=4,"abril",IF(O12=5,"mayo",IF(O12=6,"junio",IF(O12=7,"julio",IF(O12=8,"agosto",IF(O12=9,"septiembre",IF(O12=10,"octubre",IF(O12=11,"noviembre",IF(O12=12,"diciembre","REVISAR")))))))))))) -> agosto | Q12: =YEAR(H12) -> 2025 | R12: =CONCATENATE(P12,"-",Q12) -> agosto-2025 | S12: =MONTH(I12) -> 8 | T12: =IF(S12=1,"enero",IF(S12=2,"febrero",IF(S12=3,"marzo",IF(S12=4,"abril",IF(S12=5,"mayo",IF(S12=6,"junio",IF(S12=7,"julio",IF(S12=8,"agosto",IF(S12=9,"septiembre",IF(S12=10,"octubre",IF(S12=11,"noviembre",IF(S12=12,"diciembre","REVISAR")))))))))))) -> agosto | U12: =YEAR(I12) -> 2025 | V12: =CONCATENATE(T12,"-",U12) -> agosto-2025 | W12: =IFERROR(_xlfn.DAYS('Jira BUGS'!I12,'Jira BUGS'!H12),0) -> 6 | X12: =VLOOKUP(D12,SLAs!A:B,2,0) -> 21 | Y12: =IF(N12>=X12,"NO CUMPLE","CUMPLE") -> NO CUMPLE
A13: ESPC360-19693 | B13: C360_Operacional_Sprint 206 | D13: Medium | E13: CERRADO ITSM | F13: 45926.504 | H13: 45848.52 | I13: 45875 | J13: 45869 | K13: C360_Operacional_Sprint 206 | L13: 26 | M13: OPERACIONAL | N13: Resolved | O13: =MONTH(H13) -> 7 | P13: =IF(O13=1,"enero",IF(O13=2,"febrero",IF(O13=3,"marzo",IF(O13=4,"abril",IF(O13=5,"mayo",IF(O13=6,"junio",IF(O13=7,"julio",IF(O13=8,"agosto",IF(O13=9,"septiembre",IF(O13=10,"octubre",IF(O13=11,"noviembre",IF(O13=12,"diciembre","REVISAR")))))))))))) -> julio | Q13: =YEAR(H13) -> 2025 | R13: =CONCATENATE(P13,"-",Q13) -> julio-2025 | S13: =MONTH(I13) -> 8 | T13: =IF(S13=1,"enero",IF(S13=2,"febrero",IF(S13=3,"marzo",IF(S13=4,"abril",IF(S13=5,"mayo",IF(S13=6,"junio",IF(S13=7,"julio",IF(S13=8,"agosto",IF(S13=9,"septiembre",IF(S13=10,"octubre",IF(S13=11,"noviembre",IF(S13=12,"diciembre","REVISAR")))))))))))) -> agosto | U13: =YEAR(I13) -> 2025 | V13: =CONCATENATE(T13,"-",U13) -> agosto-2025 | W13: =IFERROR(_xlfn.DAYS('Jira BUGS'!I13,'Jira BUGS'!H13),0) -> 27 | X13: =VLOOKUP(D13,SLAs!A:B,2,0) -> 21 | Y13: =IF(N13>=X13,"NO CUMPLE","CUMPLE") -> NO CUMPLE
A14: ESPC360-19944 | B14: C360_Operacional_Sprint 206 - Exprés - Customer-position | C14: ERNESTO Gimeno Valiente | D14: Medium | E14: CERRADO ITSM | F14: 45926.504 | H14: 45862.377 | I14: 45869 | J14: 45862 | K14: C360_Operacional_Sprint 206 | L14: 6 | M14: OPERACIONAL | N14: Resolved | O14: =MONTH(H14) -> 7 | P14: =IF(O14=1,"enero",IF(O14=2,"febrero",IF(O14=3,"marzo",IF(O14=4,"abril",IF(O14=5,"mayo",IF(O14=6,"junio",IF(O14=7,"julio",IF(O14=8,"agosto",IF(O14=9,"septiembre",IF(O14=10,"octubre",IF(O14=11,"noviembre",IF(O14=12,"diciembre","REVISAR")))))))))))) -> julio | Q14: =YEAR(H14) -> 2025 | R14: =CONCATENATE(P14,"-",Q14) -> julio-2025 | S14: =MONTH(I14) -> 7 | T14: =IF(S14=1,"enero",IF(S14=2,"febrero",IF(S14=3,"marzo",IF(S14=4,"abril",IF(S14=5,"mayo",IF(S14=6,"junio",IF(S14=7,"julio",IF(S14=8,"agosto",IF(S14=9,"septiembre",IF(S14=10,"octubre",IF(S14=11,"noviembre",IF(S14=12,"diciembre","REVISAR")))))))))))) -> julio | U14: =YEAR(I14) -> 2025 | V14: =CONCATENATE(T14,"-",U14) -> julio-2025 | W14: =IFERROR(_xlfn.DAYS('Jira BUGS'!I14,'Jira BUGS'!H14),0) -> 7 | X14: =VLOOKUP(D14,SLAs!A:B,2,0) -> 21 | Y14: =IF(N14>=X14,"NO CUMPLE","CUMPLE") -> NO CUMPLE
A15: ESPC360-19826 | B15: C360_Operacional_Sprint 206 - Exprés | C15: ERNESTO Gimeno Valiente | D15: Medium | E15: CERRADO ITSM | F15: 45926.504 | H15: 45855.365 | I15: 45869 | J15: 45861 | K15: C360_Operacional_Sprint 206 | L15: 13 | M15: OPERACIONAL | N15: Resolved | O15: =MONTH(H15) -> 7 | P15: =IF(O15=1,"enero",IF(O15=2,"febrero",IF(O15=3,"marzo",IF(O15=4,"abril",IF(O15=5,"mayo",IF(O15=6,"junio",IF(O15=7,"julio",IF(O15=8,"agosto",IF(O15=9,"septiembre",IF(O15=10,"octubre",IF(O15=11,"noviembre",IF(O15=12,"diciembre","REVISAR")))))))))))) -> julio | Q15: =YEAR(H15) -> 2025 | R15: =CONCATENATE(P15,"-",Q15) -> julio-2025 | S15: =MONTH(I15) -> 7 | T15: =IF(S15=1,"enero",IF(S15=2,"febrero",IF(S15=3,"marzo",IF(S15=4,"abril",IF(S15=5,"mayo",IF(S15=6,"junio",IF(S15=7,"julio",IF(S15=8,"agosto",IF(S15=9,"septiembre",IF(S15=10,"octubre",IF(S15=11,"noviembre",IF(S15=12,"diciembre","REVISAR")))))))))))) -> julio | U15: =YEAR(I15) -> 2025 | V15: =CONCATENATE(T15,"-",U15) -> julio-2025 | W15: =IFERROR(_xlfn.DAYS('Jira BUGS'!I15,'Jira BUGS'!H15),0) -> 14 | X15: =VLOOKUP(D15,SLAs!A:B,2,0) -> 21 | Y15: =IF(N15>=X15,"NO CUMPLE","CUMPLE") -> NO CUMPLE
A16: ESPC360-19407 | B16: C360_Operacional_Sprint 205 | C16: ERNESTO Gimeno Valiente | D16: Medium | E16: CERRADO ITSM | F16: 45861.424 | H16: 45834.518 | I16: 45861 | J16: 45855 | K16: C360_Operacional_Sprint 205 | L16: 26 | M16: OPERACIONAL | N16: Resolved | O16: =MONTH(H16) -> 6 | P16: =IF(O16=1,"enero",IF(O16=2,"febrero",IF(O16=3,"marzo",IF(O16=4,"abril",IF(O16=5,"mayo",IF(O16=6,"junio",IF(O16=7,"julio",IF(O16=8,"agosto",IF(O16=9,"septiembre",IF(O16=10,"octubre",IF(O16=11,"noviembre",IF(O16=12,"diciembre","REVISAR")))))))))))) -> junio | Q16: =YEAR(H16) -> 2025 | R16: =CONCATENATE(P16,"-",Q16) -> junio-2025 | S16: =MONTH(I16) -> 7 | T16: =IF(S16=1,"enero",IF(S16=2,"febrero",IF(S16=3,"marzo",IF(S16=4,"abril",IF(S16=5,"mayo",IF(S16=6,"junio",IF(S16=7,"julio",IF(S16=8,"agosto",IF(S16=9,"septiembre",IF(S16=10,"octubre",IF(S16=11,"noviembre",IF(S16=12,"diciembre","REVISAR")))))))))))) -> julio | U16: =YEAR(I16) -> 2025 | V16: =CONCATENATE(T16,"-",U16) -> julio-2025 | W16: =IFERROR(_xlfn.DAYS('Jira BUGS'!I16,'Jira BUGS'!H16),0) -> 27 | X16: =VLOOKUP(D16,SLAs!A:B,2,0) -> 21 | Y16: =IF(N16>=X16,"NO CUMPLE","CUMPLE") -> NO CUMPLE
A17: ESPC360-19755 | B17: C360_Operacional_Sprint 205 - Exprés | C17: Andrei Brinza | D17: Medium | E17: CERRADO ITSM | F17: 45895.429 | H17: 45848.56 | I17: 45861 | J17: 45849 | K17: [TESTING] Ejecución pruebas de regresión C360_Operacional_Sprint 205_expres | L17: 12 | M17: OPERACIONAL | N17: Resolved | O17: =MONTH(H17) -> 7 | P17: =IF(O17=1,"enero",IF(O17=2,"febrero",IF(O17=3,"marzo",IF(O17=4,"abril",IF(O17=5,"mayo",IF(O17=6,"junio",IF(O17=7,"julio",IF(O17=8,"agosto",IF(O17=9,"septiembre",IF(O17=10,"octubre",IF(O17=11,"noviembre",IF(O17=12,"diciembre","REVISAR")))))))))))) -> julio | Q17: =YEAR(H17) -> 2025 | R17: =CONCATENATE(P17,"-",Q17) -> julio-2025 | S17: =MONTH(I17) -> 7 | T17: =IF(S17=1,"enero",IF(S17=2,"febrero",IF(S17=3,"marzo",IF(S17=4,"abril",IF(S17=5,"mayo",IF(S17=6,"junio",IF(S17=7,"julio",IF(S17=8,"agosto",IF(S17=9,"septiembre",IF(S17=10,"octubre",IF(S17=11,"noviembre",IF(S17=12,"diciembre","REVISAR")))))))))))) -> julio | U17: =YEAR(I17) -> 2025 | V17: =CONCATENATE(T17,"-",U17) -> julio-2025 | W17: =IFERROR(_xlfn.DAYS('Jira BUGS'!I17,'Jira BUGS'!H17),0) -> 13 | X17: =VLOOKUP(D17,SLAs!A:B,2,0) -> 21 | Y17: =IF(N17>=X17,"NO CUMPLE","CUMPLE") -> NO CUMPLE
A18: ESPC360-19490 | B18: C360_Operacional_Sprint 204 - Certificados | C18: ERNESTO Gimeno Valiente | D18: Medium | E18: CERRADO ITSM | F18: 45847.448 | H18: 45835.343 | I18: 45847 | J18: 45835 | K18: C360_Operacional_Sprint 204 - Certificados | L18: 11 | M18: OPERACIONAL | N18: Resolved | O18: =MONTH(H18) -> 6 | P18: =IF(O18=1,"enero",IF(O18=2,"febrero",IF(O18=3,"marzo",IF(O18=4,"abril",IF(O18=5,"mayo",IF(O18=6,"junio",IF(O18=7,"julio",IF(O18=8,"agosto",IF(O18=9,"septiembre",IF(O18=10,"octubre",IF(O18=11,"noviembre",IF(O18=12,"diciembre","REVISAR")))))))))))) -> junio | Q18: =YEAR(H18) -> 2025 | R18: =CONCATENATE(P18,"-",Q18) -> junio-2025 | S18: =MONTH(I18) -> 7 | T18: =IF(S18=1,"enero",IF(S18=2,"febrero",IF(S18=3,"marzo",IF(S18=4,"abril",IF(S18=5,"mayo",IF(S18=6,"junio",IF(S18=7,"julio",IF(S18=8,"agosto",IF(S18=9,"septiembre",IF(S18=10,"octubre",IF(S18=11,"noviembre",IF(S18=12,"diciembre","REVISAR")))))))))))) -> julio | U18: =YEAR(I18) -> 2025 | V18: =CONCATENATE(T18,"-",U18) -> julio-2025 | W18: =IFERROR(_xlfn.DAYS('Jira BUGS'!I18,'Jira BUGS'!H18),0) -> 12 | X18: =VLOOKUP(D18,SLAs!A:B,2,0) -> 21 | Y18: =IF(N18>=X18,"NO CUMPLE","CUMPLE") -> NO CUMPLE
A19: ESPC360-19162 | B19: C360_Operacional_Sprint 204 | C19: ERNESTO Gimeno Valiente | D19: Medium | E19: CERRADO ITSM | F19: 45855.507 | H19: 45820.525 | I19: 45847 | J19: 45835 | K19: C360_Operacional_Sprint 204 | L19: 26 | M19: OPERACIONAL | N19: Resolved | O19: =MONTH(H19) -> 6 | P19: =IF(O19=1,"enero",IF(O19=2,"febrero",IF(O19=3,"marzo",IF(O19=4,"abril",IF(O19=5,"mayo",IF(O19=6,"junio",IF(O19=7,"julio",IF(O19=8,"agosto",IF(O19=9,"septiembre",IF(O19=10,"octubre",IF(O19=11,"noviembre",IF(O19=12,"diciembre","REVISAR")))))))))))) -> junio | Q19: =YEAR(H19) -> 2025 | R19: =CONCATENATE(P19,"-",Q19) -> junio-2025 | S19: =MONTH(I19) -> 7 | T19: =IF(S19=1,"enero",IF(S19=2,"febrero",IF(S19=3,"marzo",IF(S19=4,"abril",IF(S19=5,"mayo",IF(S19=6,"junio",IF(S19=7,"julio",IF(S19=8,"agosto",IF(S19=9,"septiembre",IF(S19=10,"octubre",IF(S19=11,"noviembre",IF(S19=12,"diciembre","REVISAR")))))))))))) -> julio | U19: =YEAR(I19) -> 2025 | V19: =CONCATENATE(T19,"-",U19) -> julio-2025 | W19: =IFERROR(_xlfn.DAYS('Jira BUGS'!I19,'Jira BUGS'!H19),0) -> 27 | X19: =VLOOKUP(D19,SLAs!A:B,2,0) -> 21 | Y19: =IF(N19>=X19,"NO CUMPLE","CUMPLE") -> NO CUMPLE
A20: ESPC360-18907 | B20: C360_Operacional_Sprint 203 | C20: ERNESTO Gimeno Valiente | D20: Medium | E20: CERRADO ITSM | F20: 45833.742 | H20: 45806.725 | I20: 45833 | J20: 45821 | K20: C360_Operacional_Sprint 203 | L20: 26 | M20: OPERACIONAL | N20: Resolved | O20: =MONTH(H20) -> 5 | P20: =IF(O20=1,"enero",IF(O20=2,"febrero",IF(O20=3,"marzo",IF(O20=4,"abril",IF(O20=5,"mayo",IF(O20=6,"junio",IF(O20=7,"julio",IF(O20=8,"agosto",IF(O20=9,"septiembre",IF(O20=10,"octubre",IF(O20=11,"noviembre",IF(O20=12,"diciembre","REVISAR")))))))))))) -> mayo | Q20: =YEAR(H20) -> 2025 | R20: =CONCATENATE(P20,"-",Q20) -> mayo-2025 | S20: =MONTH(I20) -> 6 | T20: =IF(S20=1,"enero",IF(S20=2,"febrero",IF(S20=3,"marzo",IF(S20=4,"abril",IF(S20=5,"mayo",IF(S20=6,"junio",IF(S20=7,"julio",IF(S20=8,"agosto",IF(S20=9,"septiembre",IF(S20=10,"octubre",IF(S20=11,"noviembre",IF(S20=12,"diciembre","REVISAR")))))))))))) -> junio | U20: =YEAR(I20) -> 2025 | V20: =CONCATENATE(T20,"-",U20) -> junio-2025 | W20: =IFERROR(_xlfn.DAYS('Jira BUGS'!I20,'Jira BUGS'!H20),0) -> 27 | X20: =VLOOKUP(D20,SLAs!A:B,2,0) -> 21 | Y20: =IF(N20>=X20,"NO CUMPLE","CUMPLE") -> NO CUMPLE
A21: ESPC360-18427 | B21: C360_Operacional_Sprint 202 | C21: ERNESTO Gimeno Valiente | D21: Medium | E21: CERRADO ITSM | F21: 45834.411 | H21: 45793.632 | I21: 45833 | J21: 45813 | K21: C360_Operacional_Sprint 202 | L21: 39 | M21: OPERACIONAL | N21: Resolved | O21: =MONTH(H21) -> 5 | P21: =IF(O21=1,"enero",IF(O21=2,"febrero",IF(O21=3,"marzo",IF(O21=4,"abril",IF(O21=5,"mayo",IF(O21=6,"junio",IF(O21=7,"julio",IF(O21=8,"agosto",IF(O21=9,"septiembre",IF(O21=10,"octubre",IF(O21=11,"noviembre",IF(O21=12,"diciembre","REVISAR")))))))))))) -> mayo | Q21: =YEAR(H21) -> 2025 | R21: =CONCATENATE(P21,"-",Q21) -> mayo-2025 | S21: =MONTH(I21) -> 6 | T21: =IF(S21=1,"enero",IF(S21=2,"febrero",IF(S21=3,"marzo",IF(S21=4,"abril",IF(S21=5,"mayo",IF(S21=6,"junio",IF(S21=7,"julio",IF(S21=8,"agosto",IF(S21=9,"septiembre",IF(S21=10,"octubre",IF(S21=11,"noviembre",IF(S21=12,"diciembre","REVISAR")))))))))))) -> junio | U21: =YEAR(I21) -> 2025 | V21: =CONCATENATE(T21,"-",U21) -> junio-2025 | W21: =IFERROR(_xlfn.DAYS('Jira BUGS'!I21,'Jira BUGS'!H21),0) -> 40 | X21: =VLOOKUP(D21,SLAs!A:B,2,0) -> 21 | Y21: =IF(N21>=X21,"NO CUMPLE","CUMPLE") -> NO CUMPLE
A22: ESPC360-18426 | B22: C360_Operacional_Sprint 201_Dualidad_Gravity | C22: ERNESTO Gimeno Valiente | D22: Medium | E22: CERRADO ITSM | F22: 45813.396 | H22: 45793.53 | I22: 45813 | L22: 19 | M22: OPERACIONAL | N22: Resolved | O22: =MONTH(H22) -> 5 | P22: =IF(O22=1,"enero",IF(O22=2,"febrero",IF(O22=3,"marzo",IF(O22=4,"abril",IF(O22=5,"mayo",IF(O22=6,"junio",IF(O22=7,"julio",IF(O22=8,"agosto",IF(O22=9,"septiembre",IF(O22=10,"octubre",IF(O22=11,"noviembre",IF(O22=12,"diciembre","REVISAR")))))))))))) -> mayo | Q22: =YEAR(H22) -> 2025 | R22: =CONCATENATE(P22,"-",Q22) -> mayo-2025 | S22: =MONTH(I22) -> 6 | T22: =IF(S22=1,"enero",IF(S22=2,"febrero",IF(S22=3,"marzo",IF(S22=4,"abril",IF(S22=5,"mayo",IF(S22=6,"junio",IF(S22=7,"julio",IF(S22=8,"agosto",IF(S22=9,"septiembre",IF(S22=10,"octubre",IF(S22=11,"noviembre",IF(S22=12,"diciembre","REVISAR")))))))))))) -> junio | U22: =YEAR(I22) -> 2025 | V22: =CONCATENATE(T22,"-",U22) -> junio-2025 | W22: =IFERROR(_xlfn.DAYS('Jira BUGS'!I22,'Jira BUGS'!H22),0) -> 20 | X22: =VLOOKUP(D22,SLAs!A:B,2,0) -> 21 | Y22: =IF(N22>=X22,"NO CUMPLE","CUMPLE") -> NO CUMPLE
A23: ESPC360-18050 | B23: C360_Operacional_Sprint 201 | D23: Medium | E23: CERRADO ITSM | F23: 45849.399 | H23: 45777.773 | I23: 45812 | K23: C360_Operacional_Sprint 201 | L23: 34 | M23: OPERACIONAL | N23: Resolved | O23: =MONTH(H23) -> 4 | P23: =IF(O23=1,"enero",IF(O23=2,"febrero",IF(O23=3,"marzo",IF(O23=4,"abril",IF(O23=5,"mayo",IF(O23=6,"junio",IF(O23=7,"julio",IF(O23=8,"agosto",IF(O23=9,"septiembre",IF(O23=10,"octubre",IF(O23=11,"noviembre",IF(O23=12,"diciembre","REVISAR")))))))))))) -> abril | Q23: =YEAR(H23) -> 2025 | R23: =CONCATENATE(P23,"-",Q23) -> abril-2025 | S23: =MONTH(I23) -> 6 | T23: =IF(S23=1,"enero",IF(S23=2,"febrero",IF(S23=3,"marzo",IF(S23=4,"abril",IF(S23=5,"mayo",IF(S23=6,"junio",IF(S23=7,"julio",IF(S23=8,"agosto",IF(S23=9,"septiembre",IF(S23=10,"octubre",IF(S23=11,"noviembre",IF(S23=12,"diciembre","REVISAR")))))))))))) -> junio | U23: =YEAR(I23) -> 2025 | V23: =CONCATENATE(T23,"-",U23) -> junio-2025 | W23: =IFERROR(_xlfn.DAYS('Jira BUGS'!I23,'Jira BUGS'!H23),0) -> 35 | X23: =VLOOKUP(D23,SLAs!A:B,2,0) -> 21 | Y23: =IF(N23>=X23,"NO CUMPLE","CUMPLE") -> NO CUMPLE
A24: ESPC360-17357 | B24: [CM] ADN360_Sprint 198 Modificaciones Jobs carga-prestamos-bonificaciones-simulacion carga-prestamos-bonificaciones-actual | C24: Andrei Brinza | D24: Medium | E24: CERRADO ITSM | F24: 45812.399 | H24: 45748.735 | I24: 45812 | J24: 45751 | L24: 63 | M24: OPERACIONAL | N24: Resolved | O24: =MONTH(H24) -> 4 | P24: =IF(O24=1,"enero",IF(O24=2,"febrero",IF(O24=3,"marzo",IF(O24=4,"abril",IF(O24=5,"mayo",IF(O24=6,"junio",IF(O24=7,"julio",IF(O24=8,"agosto",IF(O24=9,"septiembre",IF(O24=10,"octubre",IF(O24=11,"noviembre",IF(O24=12,"diciembre","REVISAR")))))))))))) -> abril | Q24: =YEAR(H24) -> 2025 | R24: =CONCATENATE(P24,"-",Q24) -> abril-2025 | S24: =MONTH(I24) -> 6 | T24: =IF(S24=1,"enero",IF(S24=2,"febrero",IF(S24=3,"marzo",IF(S24=4,"abril",IF(S24=5,"mayo",IF(S24=6,"junio",IF(S24=7,"julio",IF(S24=8,"agosto",IF(S24=9,"septiembre",IF(S24=10,"octubre",IF(S24=11,"noviembre",IF(S24=12,"diciembre","REVISAR")))))))))))) -> junio | U24: =YEAR(I24) -> 2025 | V24: =CONCATENATE(T24,"-",U24) -> junio-2025 | W24: =IFERROR(_xlfn.DAYS('Jira BUGS'!I24,'Jira BUGS'!H24),0) -> 64 | X24: =VLOOKUP(D24,SLAs!A:B,2,0) -> 21 | Y24: =IF(N24>=X24,"NO CUMPLE","CUMPLE") -> NO CUMPLE
A25: ESPC360-17664 | B25: [CM] ADN360_Sprint 198 Creacion Jobs carga-tipos-movimientos , carga-tipos-movimientos-gs | C25: Andrei Brinza | D25: Medium | E25: CERRADO ITSM | F25: 45812.399 | H25: 45758.544 | I25: 45812 | J25: 45758 | L25: 53 | M25: OPERACIONAL | N25: Resolved | O25: =MONTH(H25) -> 4 | P25: =IF(O25=1,"enero",IF(O25=2,"febrero",IF(O25=3,"marzo",IF(O25=4,"abril",IF(O25=5,"mayo",IF(O25=6,"junio",IF(O25=7,"julio",IF(O25=8,"agosto",IF(O25=9,"septiembre",IF(O25=10,"octubre",IF(O25=11,"noviembre",IF(O25=12,"diciembre","REVISAR")))))))))))) -> abril | Q25: =YEAR(H25) -> 2025 | R25: =CONCATENATE(P25,"-",Q25) -> abril-2025 | S25: =MONTH(I25) -> 6 | T25: =IF(S25=1,"enero",IF(S25=2,"febrero",IF(S25=3,"marzo",IF(S25=4,"abril",IF(S25=5,"mayo",IF(S25=6,"junio",IF(S25=7,"julio",IF(S25=8,"agosto",IF(S25=9,"septiembre",IF(S25=10,"octubre",IF(S25=11,"noviembre",IF(S25=12,"diciembre","REVISAR")))))))))))) -> junio | U25: =YEAR(I25) -> 2025 | V25: =CONCATENATE(T25,"-",U25) -> junio-2025 | W25: =IFERROR(_xlfn.DAYS('Jira BUGS'!I25,'Jira BUGS'!H25),0) -> 54 | X25: =VLOOKUP(D25,SLAs!A:B,2,0) -> 21 | Y25: =IF(N25>=X25,"NO CUMPLE","CUMPLE") -> NO CUMPLE
A26: ESPC360-17189 | B26: [CM] Sprint 198 - [Portal Deudor] update-contratos-opening | C26: ERIC REVELLES SEGALES | D26: Medium | E26: CERRADO ITSM | F26: 45895.433 | H26: 45743.634 | I26: 45799 | J26: 45743 | L26: 55 | M26: OPERACIONAL | N26: Resolved | O26: =MONTH(H26) -> 3 | P26: =IF(O26=1,"enero",IF(O26=2,"febrero",IF(O26=3,"marzo",IF(O26=4,"abril",IF(O26=5,"mayo",IF(O26=6,"junio",IF(O26=7,"julio",IF(O26=8,"agosto",IF(O26=9,"septiembre",IF(O26=10,"octubre",IF(O26=11,"noviembre",IF(O26=12,"diciembre","REVISAR")))))))))))) -> marzo | Q26: =YEAR(H26) -> 2025 | R26: =CONCATENATE(P26,"-",Q26) -> marzo-2025 | S26: =MONTH(I26) -> 5 | T26: =IF(S26=1,"enero",IF(S26=2,"febrero",IF(S26=3,"marzo",IF(S26=4,"abril",IF(S26=5,"mayo",IF(S26=6,"junio",IF(S26=7,"julio",IF(S26=8,"agosto",IF(S26=9,"septiembre",IF(S26=10,"octubre",IF(S26=11,"noviembre",IF(S26=12,"diciembre","REVISAR")))))))))))) -> mayo | U26: =YEAR(I26) -> 2025 | V26: =CONCATENATE(T26,"-",U26) -> mayo-2025 | W26: =IFERROR(_xlfn.DAYS('Jira BUGS'!I26,'Jira BUGS'!H26),0) -> 56 | X26: =VLOOKUP(D26,SLAs!A:B,2,0) -> 21 | Y26: =IF(N26>=X26,"NO CUMPLE","CUMPLE") -> NO CUMPLE
A27: ESPC360-17713 | B27: C360_Operacional_Sprint 200 | C27: ERNESTO Gimeno Valiente | D27: Medium | E27: CERRADO ITSM | F27: 45797.081 | H27: 45768.719 | I27: 45796 | J27: 45779 | K27: C360_Operacional_Sprint 200 | L27: 27 | M27: OPERACIONAL | N27: Resolved | O27: =MONTH(H27) -> 4 | P27: =IF(O27=1,"enero",IF(O27=2,"febrero",IF(O27=3,"marzo",IF(O27=4,"abril",IF(O27=5,"mayo",IF(O27=6,"junio",IF(O27=7,"julio",IF(O27=8,"agosto",IF(O27=9,"septiembre",IF(O27=10,"octubre",IF(O27=11,"noviembre",IF(O27=12,"diciembre","REVISAR")))))))))))) -> abril | Q27: =YEAR(H27) -> 2025 | R27: =CONCATENATE(P27,"-",Q27) -> abril-2025 | S27: =MONTH(I27) -> 5 | T27: =IF(S27=1,"enero",IF(S27=2,"febrero",IF(S27=3,"marzo",IF(S27=4,"abril",IF(S27=5,"mayo",IF(S27=6,"junio",IF(S27=7,"julio",IF(S27=8,"agosto",IF(S27=9,"septiembre",IF(S27=10,"octubre",IF(S27=11,"noviembre",IF(S27=12,"diciembre","REVISAR")))))))))))) -> mayo | U27: =YEAR(I27) -> 2025 | V27: =CONCATENATE(T27,"-",U27) -> mayo-2025 | W27: =IFERROR(_xlfn.DAYS('Jira BUGS'!I27,'Jira BUGS'!H27),0) -> 28 | X27: =VLOOKUP(D27,SLAs!A:B,2,0) -> 21 | Y27: =IF(N27>=X27,"NO CUMPLE","CUMPLE") -> NO CUMPLE
A28: ESPC360-16743 | B28: [CM] Sprint 197 - [Databricks] - Modificar la malla Control-M en PRE para engancharlo a las condiciones de ingesta cloud | C28: BORJA CORTIJO LAJARA | D28: Medium | E28: CERRADO ITSM | F28: 45895.433 | H28: 45727.469 | I28: 45796 | J28: 45727 | L28: 68 | M28: OPERACIONAL | N28: Resolved | O28: =MONTH(H28) -> 3 | P28: =IF(O28=1,"enero",IF(O28=2,"febrero",IF(O28=3,"marzo",IF(O28=4,"abril",IF(O28=5,"mayo",IF(O28=6,"junio",IF(O28=7,"julio",IF(O28=8,"agosto",IF(O28=9,"septiembre",IF(O28=10,"octubre",IF(O28=11,"noviembre",IF(O28=12,"diciembre","REVISAR")))))))))))) -> marzo | Q28: =YEAR(H28) -> 2025 | R28: =CONCATENATE(P28,"-",Q28) -> marzo-2025 | S28: =MONTH(I28) -> 5 | T28: =IF(S28=1,"enero",IF(S28=2,"febrero",IF(S28=3,"marzo",IF(S28=4,"abril",IF(S28=5,"mayo",IF(S28=6,"junio",IF(S28=7,"julio",IF(S28=8,"agosto",IF(S28=9,"septiembre",IF(S28=10,"octubre",IF(S28=11,"noviembre",IF(S28=12,"diciembre","REVISAR")))))))))))) -> mayo | U28: =YEAR(I28) -> 2025 | V28: =CONCATENATE(T28,"-",U28) -> mayo-2025 | W28: =IFERROR(_xlfn.DAYS('Jira BUGS'!I28,'Jira BUGS'!H28),0) -> 69 | X28: =VLOOKUP(D28,SLAs!A:B,2,0) -> 21 | Y28: =IF(N28>=X28,"NO CUMPLE","CUMPLE") -> NO CUMPLE
A29: ESPC360-17055 | B29: C360_Operacional_Sprint 198 | D29: Medium | E29: CERRADO ITSM | F29: 45784.582 | H29: 45736.614 | I29: 45784 | J29: 45751 | K29: C360_Operacional_Sprint 198 | L29: 47 | M29: OPERACIONAL | N29: Resolved | O29: =MONTH(H29) -> 3 | P29: =IF(O29=1,"enero",IF(O29=2,"febrero",IF(O29=3,"marzo",IF(O29=4,"abril",IF(O29=5,"mayo",IF(O29=6,"junio",IF(O29=7,"julio",IF(O29=8,"agosto",IF(O29=9,"septiembre",IF(O29=10,"octubre",IF(O29=11,"noviembre",IF(O29=12,"diciembre","REVISAR")))))))))))) -> marzo | Q29: =YEAR(H29) -> 2025 | R29: =CONCATENATE(P29,"-",Q29) -> marzo-2025 | S29: =MONTH(I29) -> 5 | T29: =IF(S29=1,"enero",IF(S29=2,"febrero",IF(S29=3,"marzo",IF(S29=4,"abril",IF(S29=5,"mayo",IF(S29=6,"junio",IF(S29=7,"julio",IF(S29=8,"agosto",IF(S29=9,"septiembre",IF(S29=10,"octubre",IF(S29=11,"noviembre",IF(S29=12,"diciembre","REVISAR")))))))))))) -> mayo | U29: =YEAR(I29) -> 2025 | V29: =CONCATENATE(T29,"-",U29) -> mayo-2025 | W29: =IFERROR(_xlfn.DAYS('Jira BUGS'!I29,'Jira BUGS'!H29),0) -> 48 | X29: =VLOOKUP(D29,SLAs!A:B,2,0) -> 21 | Y29: =IF(N29>=X29,"NO CUMPLE","CUMPLE") -> NO CUMPLE
A30: ESPC360-18044 | B30: C360_Operacional_HotFix_BGM | C30: ERNESTO Gimeno Valiente | D30: Medium | E30: CERRADO ITSM | F30: 45784.112 | H30: 45777.566 | I30: 45784 | L30: 5 | M30: OPERACIONAL | N30: Resolved | O30: =MONTH(H30) -> 4 | P30: =IF(O30=1,"enero",IF(O30=2,"febrero",IF(O30=3,"marzo",IF(O30=4,"abril",IF(O30=5,"mayo",IF(O30=6,"junio",IF(O30=7,"julio",IF(O30=8,"agosto",IF(O30=9,"septiembre",IF(O30=10,"octubre",IF(O30=11,"noviembre",IF(O30=12,"diciembre","REVISAR")))))))))))) -> abril | Q30: =YEAR(H30) -> 2025 | R30: =CONCATENATE(P30,"-",Q30) -> abril-2025 | S30: =MONTH(I30) -> 5 | T30: =IF(S30=1,"enero",IF(S30=2,"febrero",IF(S30=3,"marzo",IF(S30=4,"abril",IF(S30=5,"mayo",IF(S30=6,"junio",IF(S30=7,"julio",IF(S30=8,"agosto",IF(S30=9,"septiembre",IF(S30=10,"octubre",IF(S30=11,"noviembre",IF(S30=12,"diciembre","REVISAR")))))))))))) -> mayo | U30: =YEAR(I30) -> 2025 | V30: =CONCATENATE(T30,"-",U30) -> mayo-2025 | W30: =IFERROR(_xlfn.DAYS('Jira BUGS'!I30,'Jira BUGS'!H30),0) -> 7 | X30: =VLOOKUP(D30,SLAs!A:B,2,0) -> 21 | Y30: =IF(N30>=X30,"NO CUMPLE","CUMPLE") -> NO CUMPLE
A31: ESPC360-17446 | B31: C360_Operacional_Sprint 199 | C31: ERNESTO Gimeno Valiente | D31: Medium | E31: CERRADO ITSM | F31: 45786.343 | H31: 45750.675 | I31: 45784 | J31: 45769 | K31: C360_Operacional_Sprint 199 | L31: 32 | M31: OPERACIONAL | N31: Resolved | O31: =MONTH(H31) -> 4 | P31: =IF(O31=1,"enero",IF(O31=2,"febrero",IF(O31=3,"marzo",IF(O31=4,"abril",IF(O31=5,"mayo",IF(O31=6,"junio",IF(O31=7,"julio",IF(O31=8,"agosto",IF(O31=9,"septiembre",IF(O31=10,"octubre",IF(O31=11,"noviembre",IF(O31=12,"diciembre","REVISAR")))))))))))) -> abril | Q31: =YEAR(H31) -> 2025 | R31: =CONCATENATE(P31,"-",Q31) -> abril-2025 | S31: =MONTH(I31) -> 5 | T31: =IF(S31=1,"enero",IF(S31=2,"febrero",IF(S31=3,"marzo",IF(S31=4,"abril",IF(S31=5,"mayo",IF(S31=6,"junio",IF(S31=7,"julio",IF(S31=8,"agosto",IF(S31=9,"septiembre",IF(S31=10,"octubre",IF(S31=11,"noviembre",IF(S31=12,"diciembre","REVISAR")))))))))))) -> mayo | U31: =YEAR(I31) -> 2025 | V31: =CONCATENATE(T31,"-",U31) -> mayo-2025 | W31: =IFERROR(_xlfn.DAYS('Jira BUGS'!I31,'Jira BUGS'!H31),0) -> 34 | X31: =VLOOKUP(D31,SLAs!A:B,2,0) -> 21 | Y31: =IF(N31>=X31,"NO CUMPLE","CUMPLE") -> NO CUMPLE
A32: ESPC360-17380 | B32: C360_Operacional_HotFix_Servicios_Digitales_Santander_Go | C32: ERNESTO Gimeno Valiente | D32: Medium | E32: CERRADO ITSM | F32: 45784.111 | H32: 45750.525 | I32: 45784 | J32: 45782 | L32: 32 | M32: OPERACIONAL | N32: Resolved | O32: =MONTH(H32) -> 4 | P32: =IF(O32=1,"enero",IF(O32=2,"febrero",IF(O32=3,"marzo",IF(O32=4,"abril",IF(O32=5,"mayo",IF(O32=6,"junio",IF(O32=7,"julio",IF(O32=8,"agosto",IF(O32=9,"septiembre",IF(O32=10,"octubre",IF(O32=11,"noviembre",IF(O32=12,"diciembre","REVISAR")))))))))))) -> abril | Q32: =YEAR(H32) -> 2025 | R32: =CONCATENATE(P32,"-",Q32) -> abril-2025 | S32: =MONTH(I32) -> 5 | T32: =IF(S32=1,"enero",IF(S32=2,"febrero",IF(S32=3,"marzo",IF(S32=4,"abril",IF(S32=5,"mayo",IF(S32=6,"junio",IF(S32=7,"julio",IF(S32=8,"agosto",IF(S32=9,"septiembre",IF(S32=10,"octubre",IF(S32=11,"noviembre",IF(S32=12,"diciembre","REVISAR")))))))))))) -> mayo | U32: =YEAR(I32) -> 2025 | V32: =CONCATENATE(T32,"-",U32) -> mayo-2025 | W32: =IFERROR(_xlfn.DAYS('Jira BUGS'!I32,'Jira BUGS'!H32),0) -> 34 | X32: =VLOOKUP(D32,SLAs!A:B,2,0) -> 21 | Y32: =IF(N32>=X32,"NO CUMPLE","CUMPLE") -> NO CUMPLE
A33: ESPC360-16744 | B33: [CM] Desplanificación fichero ingesta planesempleo proceso en PRE | C33: BORJA CORTIJO LAJARA | D33: Medium | E33: CERRADO ITSM | F33: 45770.616 | H33: 45727.478 | I33: 45770 | J33: 45729 | L33: 42 | M33: OPERACIONAL | N33: Resolved | O33: =MONTH(H33) -> 3 | P33: =IF(O33=1,"enero",IF(O33=2,"febrero",IF(O33=3,"marzo",IF(O33=4,"abril",IF(O33=5,"mayo",IF(O33=6,"junio",IF(O33=7,"julio",IF(O33=8,"agosto",IF(O33=9,"septiembre",IF(O33=10,"octubre",IF(O33=11,"noviembre",IF(O33=12,"diciembre","REVISAR")))))))))))) -> marzo | Q33: =YEAR(H33) -> 2025 | R33: =CONCATENATE(P33,"-",Q33) -> marzo-2025 | S33: =MONTH(I33) -> 4 | T33: =IF(S33=1,"enero",IF(S33=2,"febrero",IF(S33=3,"marzo",IF(S33=4,"abril",IF(S33=5,"mayo",IF(S33=6,"junio",IF(S33=7,"julio",IF(S33=8,"agosto",IF(S33=9,"septiembre",IF(S33=10,"octubre",IF(S33=11,"noviembre",IF(S33=12,"diciembre","REVISAR")))))))))))) -> abril | U33: =YEAR(I33) -> 2025 | V33: =CONCATENATE(T33,"-",U33) -> abril-2025 | W33: =IFERROR(_xlfn.DAYS('Jira BUGS'!I33,'Jira BUGS'!H33),0) -> 43 | X33: =VLOOKUP(D33,SLAs!A:B,2,0) -> 21 | Y33: =IF(N33>=X33,"NO CUMPLE","CUMPLE") -> NO CUMPLE
A34: ESPC360-17120 | B34: [CM] Sprint 198 - [Portal Deudor] Batch para cargar las cestas/agrupaciones asociadas a los contratos | C34: JOSE FELIZ HERNANDEZ | D34: Medium | E34: CERRADO ITSM | F34: 45895.433 | H34: 45740.661 | I34: 45769 | L34: 28 | M34: OPERACIONAL | N34: Resolved | O34: =MONTH(H34) -> 3 | P34: =IF(O34=1,"enero",IF(O34=2,"febrero",IF(O34=3,"marzo",IF(O34=4,"abril",IF(O34=5,"mayo",IF(O34=6,"junio",IF(O34=7,"julio",IF(O34=8,"agosto",IF(O34=9,"septiembre",IF(O34=10,"octubre",IF(O34=11,"noviembre",IF(O34=12,"diciembre","REVISAR")))))))))))) -> marzo | Q34: =YEAR(H34) -> 2025 | R34: =CONCATENATE(P34,"-",Q34) -> marzo-2025 | S34: =MONTH(I34) -> 4 | T34: =IF(S34=1,"enero",IF(S34=2,"febrero",IF(S34=3,"marzo",IF(S34=4,"abril",IF(S34=5,"mayo",IF(S34=6,"junio",IF(S34=7,"julio",IF(S34=8,"agosto",IF(S34=9,"septiembre",IF(S34=10,"octubre",IF(S34=11,"noviembre",IF(S34=12,"diciembre","REVISAR")))))))))))) -> abril | U34: =YEAR(I34) -> 2025 | V34: =CONCATENATE(T34,"-",U34) -> abril-2025 | W34: =IFERROR(_xlfn.DAYS('Jira BUGS'!I34,'Jira BUGS'!H34),0) -> 29 | X34: =VLOOKUP(D34,SLAs!A:B,2,0) -> 21 | Y34: =IF(N34>=X34,"NO CUMPLE","CUMPLE") -> NO CUMPLE
A35: ESPC360-16230 | B35: [CM] Sprint 196 - [SmartPricing] Creación proceso Batch actualización | C35: CARLOS Camacho Menchero | D35: Medium | E35: CERRADO ITSM | F35: 45895.435 | H35: 45714.375 | I35: 45758 | J35: 45714 | L35: 43 | M35: OPERACIONAL | N35: Resolved | O35: =MONTH(H35) -> 2 | P35: =IF(O35=1,"enero",IF(O35=2,"febrero",IF(O35=3,"marzo",IF(O35=4,"abril",IF(O35=5,"mayo",IF(O35=6,"junio",IF(O35=7,"julio",IF(O35=8,"agosto",IF(O35=9,"septiembre",IF(O35=10,"octubre",IF(O35=11,"noviembre",IF(O35=12,"diciembre","REVISAR")))))))))))) -> febrero | Q35: =YEAR(H35) -> 2025 | R35: =CONCATENATE(P35,"-",Q35) -> febrero-2025 | S35: =MONTH(I35) -> 4 | T35: =IF(S35=1,"enero",IF(S35=2,"febrero",IF(S35=3,"marzo",IF(S35=4,"abril",IF(S35=5,"mayo",IF(S35=6,"junio",IF(S35=7,"julio",IF(S35=8,"agosto",IF(S35=9,"septiembre",IF(S35=10,"octubre",IF(S35=11,"noviembre",IF(S35=12,"diciembre","REVISAR")))))))))))) -> abril | U35: =YEAR(I35) -> 2025 | V35: =CONCATENATE(T35,"-",U35) -> abril-2025 | W35: =IFERROR(_xlfn.DAYS('Jira BUGS'!I35,'Jira BUGS'!H35),0) -> 44 | X35: =VLOOKUP(D35,SLAs!A:B,2,0) -> 21 | Y35: =IF(N35>=X35,"NO CUMPLE","CUMPLE") -> NO CUMPLE
A36: ESPC360-16562 | B36: C360_Operacional_Sprint 197 | C36: ERNESTO Gimeno Valiente | D36: Medium | E36: CERRADO ITSM | F36: 45756.524 | H36: 45722.548 | I36: 45756 | J36: 45741 | K36: C360_Operacional_Sprint 197 | L36: 33 | M36: OPERACIONAL | N36: Resolved | O36: =MONTH(H36) -> 3 | P36: =IF(O36=1,"enero",IF(O36=2,"febrero",IF(O36=3,"marzo",IF(O36=4,"abril",IF(O36=5,"mayo",IF(O36=6,"junio",IF(O36=7,"julio",IF(O36=8,"agosto",IF(O36=9,"septiembre",IF(O36=10,"octubre",IF(O36=11,"noviembre",IF(O36=12,"diciembre","REVISAR")))))))))))) -> marzo | Q36: =YEAR(H36) -> 2025 | R36: =CONCATENATE(P36,"-",Q36) -> marzo-2025 | S36: =MONTH(I36) -> 4 | T36: =IF(S36=1,"enero",IF(S36=2,"febrero",IF(S36=3,"marzo",IF(S36=4,"abril",IF(S36=5,"mayo",IF(S36=6,"junio",IF(S36=7,"julio",IF(S36=8,"agosto",IF(S36=9,"septiembre",IF(S36=10,"octubre",IF(S36=11,"noviembre",IF(S36=12,"diciembre","REVISAR")))))))))))) -> abril | U36: =YEAR(I36) -> 2025 | V36: =CONCATENATE(T36,"-",U36) -> abril-2025 | W36: =IFERROR(_xlfn.DAYS('Jira BUGS'!I36,'Jira BUGS'!H36),0) -> 34 | X36: =VLOOKUP(D36,SLAs!A:B,2,0) -> 21 | Y36: =IF(N36>=X36,"NO CUMPLE","CUMPLE") -> NO CUMPLE
A37: ESPC360-16947 | B37: C360_Operacional_Fix_Recarga_TasasDemora_préstamos | C37: ERNESTO Gimeno Valiente | D37: Medium | E37: CERRADO ITSM | F37: 45750.477 | H37: 45734.581 | I37: 45750 | J37: 45737 | L37: 15 | M37: OPERACIONAL | N37: Resolved | O37: =MONTH(H37) -> 3 | P37: =IF(O37=1,"enero",IF(O37=2,"febrero",IF(O37=3,"marzo",IF(O37=4,"abril",IF(O37=5,"mayo",IF(O37=6,"junio",IF(O37=7,"julio",IF(O37=8,"agosto",IF(O37=9,"septiembre",IF(O37=10,"octubre",IF(O37=11,"noviembre",IF(O37=12,"diciembre","REVISAR")))))))))))) -> marzo | Q37: =YEAR(H37) -> 2025 | R37: =CONCATENATE(P37,"-",Q37) -> marzo-2025 | S37: =MONTH(I37) -> 4 | T37: =IF(S37=1,"enero",IF(S37=2,"febrero",IF(S37=3,"marzo",IF(S37=4,"abril",IF(S37=5,"mayo",IF(S37=6,"junio",IF(S37=7,"julio",IF(S37=8,"agosto",IF(S37=9,"septiembre",IF(S37=10,"octubre",IF(S37=11,"noviembre",IF(S37=12,"diciembre","REVISAR")))))))))))) -> abril | U37: =YEAR(I37) -> 2025 | V37: =CONCATENATE(T37,"-",U37) -> abril-2025 | W37: =IFERROR(_xlfn.DAYS('Jira BUGS'!I37,'Jira BUGS'!H37),0) -> 16 | X37: =VLOOKUP(D37,SLAs!A:B,2,0) -> 21 | Y37: =IF(N37>=X37,"NO CUMPLE","CUMPLE") -> NO CUMPLE
A38: ESPC360-16517 | B38: [CM] ADN360_Sprint 196 Nuevo Job update-contratos-ico | C38: CARLOS Camacho Menchero | D38: Medium | E38: CERRADO ITSM | F38: 45747.77 | H38: 45720.543 | I38: 45747 | J38: 45720 | L38: 26 | M38: OPERACIONAL | N38: Resolved | O38: =MONTH(H38) -> 3 | P38: =IF(O38=1,"enero",IF(O38=2,"febrero",IF(O38=3,"marzo",IF(O38=4,"abril",IF(O38=5,"mayo",IF(O38=6,"junio",IF(O38=7,"julio",IF(O38=8,"agosto",IF(O38=9,"septiembre",IF(O38=10,"octubre",IF(O38=11,"noviembre",IF(O38=12,"diciembre","REVISAR")))))))))))) -> marzo | Q38: =YEAR(H38) -> 2025 | R38: =CONCATENATE(P38,"-",Q38) -> marzo-2025 | S38: =MONTH(I38) -> 3 | T38: =IF(S38=1,"enero",IF(S38=2,"febrero",IF(S38=3,"marzo",IF(S38=4,"abril",IF(S38=5,"mayo",IF(S38=6,"junio",IF(S38=7,"julio",IF(S38=8,"agosto",IF(S38=9,"septiembre",IF(S38=10,"octubre",IF(S38=11,"noviembre",IF(S38=12,"diciembre","REVISAR")))))))))))) -> marzo | U38: =YEAR(I38) -> 2025 | V38: =CONCATENATE(T38,"-",U38) -> marzo-2025 | W38: =IFERROR(_xlfn.DAYS('Jira BUGS'!I38,'Jira BUGS'!H38),0) -> 27 | X38: =VLOOKUP(D38,SLAs!A:B,2,0) -> 21 | Y38: =IF(N38>=X38,"NO CUMPLE","CUMPLE") -> NO CUMPLE
A39: ESPC360-16212 | B39: [CM] ADN360_Sprint 195 Nuevo Job update-contratos-titulizados | C39: CARLOS Camacho Menchero | D39: Medium | E39: CERRADO ITSM | F39: 45740.508 | H39: 45713.465 | I39: 45740 | J39: 45713 | L39: 26 | M39: OPERACIONAL | N39: Resolved | O39: =MONTH(H39) -> 2 | P39: =IF(O39=1,"enero",IF(O39=2,"febrero",IF(O39=3,"marzo",IF(O39=4,"abril",IF(O39=5,"mayo",IF(O39=6,"junio",IF(O39=7,"julio",IF(O39=8,"agosto",IF(O39=9,"septiembre",IF(O39=10,"octubre",IF(O39=11,"noviembre",IF(O39=12,"diciembre","REVISAR")))))))))))) -> febrero | Q39: =YEAR(H39) -> 2025 | R39: =CONCATENATE(P39,"-",Q39) -> febrero-2025 | S39: =MONTH(I39) -> 3 | T39: =IF(S39=1,"enero",IF(S39=2,"febrero",IF(S39=3,"marzo",IF(S39=4,"abril",IF(S39=5,"mayo",IF(S39=6,"junio",IF(S39=7,"julio",IF(S39=8,"agosto",IF(S39=9,"septiembre",IF(S39=10,"octubre",IF(S39=11,"noviembre",IF(S39=12,"diciembre","REVISAR")))))))))))) -> marzo | U39: =YEAR(I39) -> 2025 | V39: =CONCATENATE(T39,"-",U39) -> marzo-2025 | W39: =IFERROR(_xlfn.DAYS('Jira BUGS'!I39,'Jira BUGS'!H39),0) -> 27 | X39: =VLOOKUP(D39,SLAs!A:B,2,0) -> 21 | Y39: =IF(N39>=X39,"NO CUMPLE","CUMPLE") -> NO CUMPLE
A40: ESPC360-16862 | B40: C360_Operacional_FIX_Tarjetas | C40: ERNESTO Gimeno Valiente | D40: Medium | E40: CERRADO ITSM | F40: 45735.609 | H40: 45730.478 | I40: 45735 | J40: 45730 | L40: 4 | M40: OPERACIONAL | N40: Resolved | O40: =MONTH(H40) -> 3 | P40: =IF(O40=1,"enero",IF(O40=2,"febrero",IF(O40=3,"marzo",IF(O40=4,"abril",IF(O40=5,"mayo",IF(O40=6,"junio",IF(O40=7,"julio",IF(O40=8,"agosto",IF(O40=9,"septiembre",IF(O40=10,"octubre",IF(O40=11,"noviembre",IF(O40=12,"diciembre","REVISAR")))))))))))) -> marzo | Q40: =YEAR(H40) -> 2025 | R40: =CONCATENATE(P40,"-",Q40) -> marzo-2025 | S40: =MONTH(I40) -> 3 | T40: =IF(S40=1,"enero",IF(S40=2,"febrero",IF(S40=3,"marzo",IF(S40=4,"abril",IF(S40=5,"mayo",IF(S40=6,"junio",IF(S40=7,"julio",IF(S40=8,"agosto",IF(S40=9,"septiembre",IF(S40=10,"octubre",IF(S40=11,"noviembre",IF(S40=12,"diciembre","REVISAR")))))))))))) -> marzo | U40: =YEAR(I40) -> 2025 | V40: =CONCATENATE(T40,"-",U40) -> marzo-2025 | W40: =IFERROR(_xlfn.DAYS('Jira BUGS'!I40,'Jira BUGS'!H40),0) -> 5 | X40: =VLOOKUP(D40,SLAs!A:B,2,0) -> 21 | Y40: =IF(N40>=X40,"NO CUMPLE","CUMPLE") -> NO CUMPLE
...

Sheet Datos Gráficos BUGs
A1: BUGS POR FECHA DE CREACIÓN
A3: Etiquetas de fila | B3: Cuenta de Release | C3: Promedio de Días Resolucion | K3: SLAs
A4: septiembre-2024 | B4: 2 | C4: 127.5
A5: octubre-2024 | B5: 1 | C5: 74
A6: noviembre-2024 | B6: 3 | C6: 70.666667
A7: diciembre-2024 | B7: 3 | C7: 49.333333
A8: enero-2025 | B8: 4 | C8: 26
A9: febrero-2025 | B9: 10 | C9: 22.7
A10: (en blanco)
A11: marzo-2025 | B11: 6 | C11: 19.166667
A12: Total general | B12: 29 | C12: 39.137931
A23: BUGS POR FECHA DE RESOLUCIÓN
A25: Etiquetas de fila | B25: Cuenta de Bugs
A26: enero-2025 | B26: 8
A27: febrero-2025 | B27: 7
A28: Total general | B28: 15
A44: BUGS CANCELADOS POR FECHA DE CREACIÓN
A48: Etiquetas de fila | B48: Cuenta de Bugs
A49: diciembre-2024 | B49: 3
A50: febrero-2025 | B50: 10
A51: noviembre-2024 | B51: 3
A52: octubre-2024 | B52: 1
A53: septiembre-2024 | B53: 2
A54: (en blanco)
A55: enero-2025 | B55: 4
A56: marzo-2025 | B56: 6
A57: Total general | B57: 29
A63: ENTRADAS Y SALIDAS DE BUGS
A67: Mes | B67: Bugs Abiertos | C67: Bugs Cerrados
A68: enero-2025 | B68: =COUNTIFS('Jira BUGS'!R:R,Tabla2[[#This Row],[Mes]]) -> 4 | C68: =COUNTIFS('Jira BUGS'!V:V,Tabla2[[#This Row],[Mes]]) -> 8
A69: febrero-2025 | B69: =COUNTIFS('Jira BUGS'!R:R,Tabla2[[#This Row],[Mes]]) -> 10 | C69: =COUNTIFS('Jira BUGS'!V:V,Tabla2[[#This Row],[Mes]]) -> 7
A70: marzo-2025 | B70: =COUNTIFS('Jira BUGS'!R:R,Tabla2[[#This Row],[Mes]]) -> 10 | C70: =COUNTIFS('Jira BUGS'!V:V,Tabla2[[#This Row],[Mes]]) -> 10
A71: abril-2025 | B71: =COUNTIFS('Jira BUGS'!R:R,Tabla2[[#This Row],[Mes]]) -> 7 | C71: =COUNTIFS('Jira BUGS'!V:V,Tabla2[[#This Row],[Mes]]) -> 5
A72: mayo-2025 | B72: =COUNTIFS('Jira BUGS'!R:R,Tabla2[[#This Row],[Mes]]) -> 3 | C72: =COUNTIFS('Jira BUGS'!V:V,Tabla2[[#This Row],[Mes]]) -> 7
A73: junio-2025 | B73: =COUNTIFS('Jira BUGS'!R:R,Tabla2[[#This Row],[Mes]]) -> 3 | C73: =COUNTIFS('Jira BUGS'!V:V,Tabla2[[#This Row],[Mes]]) -> 6
A74: julio-2025 | B74: =COUNTIFS('Jira BUGS'!R:R,Tabla2[[#This Row],[Mes]]) -> 6 | C74: =COUNTIFS('Jira BUGS'!V:V,Tabla2[[#This Row],[Mes]]) -> 6
A75: agosto-2025 | B75: =COUNTIFS('Jira BUGS'!R:R,Tabla2[[#This Row],[Mes]]) -> 4 | C75: =COUNTIFS('Jira BUGS'!V:V,Tabla2[[#This Row],[Mes]]) -> 3
A76: septiembre-2025 | B76: =COUNTIFS('Jira BUGS'!R:R,Tabla2[[#This Row],[Mes]]) -> 3 | C76: =COUNTIFS('Jira BUGS'!V:V,Tabla2[[#This Row],[Mes]]) -> 5
A77: octubre-2025 | B77: =COUNTIFS('Jira BUGS'!R:R,Tabla2[[#This Row],[Mes]]) -> 2 | C77: =COUNTIFS('Jira BUGS'!V:V,Tabla2[[#This Row],[Mes]]) -> 4
A78: noviembre-2025 | B78: =COUNTIFS('Jira BUGS'!R:R,Tabla2[[#This Row],[Mes]]) -> 0 | C78: =COUNTIFS('Jira BUGS'!V:V,Tabla2[[#This Row],[Mes]]) -> 0
...

Sheet SLAs
A1: Prioridad | B1: SLA (días)
A2: Highest | B2: 7
A3: High | B3: 14
A4: Medium | B4: 21

Sheet Cálculos
A1: issue | B1: Días Resolucion | C1: Mes bug creado | D1: Mes bug resolucion | E1: Prioridad | F1: Componente | G1: Origen Bug | H1: Columna1 | J1: Mes creación | K1: total | P1: Componentes quitando duplicados | Q1: conteo
A2: ='Jira BUGS'!A2 -> ESPC360-21480 | B2: =IFERROR(NETWORKDAYS('Jira BUGS'!D2,'Jira BUGS'!E2),0) -> 0 | C2: ='Jira BUGS'!O2 -> 10 | D2: ='Jira BUGS'!S2 -> 10 | E2: ='Jira BUGS'!J2 -> 45946 | F2: ='Jira BUGS'!C2 -> ERNESTO Gimeno Valiente | G2: ='Jira BUGS'!G2 | J2: {=_xlfn.UNIQUE($C$2:$C$122)} -> 10 | K2: =COUNTIF($C$2:$C$1030,$J2) -> 3 | P2: {=_xlfn.UNIQUE(F2:F1030)} -> ERNESTO Gimeno Valiente | Q2: =COUNTIF($F$2:$F$1030,$P2) -> 35
A3: ='Jira BUGS'!A3 -> ESPC360-21196 | B3: =IFERROR(NETWORKDAYS('Jira BUGS'!D3,'Jira BUGS'!E3),0) -> 0 | C3: ='Jira BUGS'!O3 -> 10 | D3: ='Jira BUGS'!S3 -> 10 | E3: ='Jira BUGS'!J3 -> 45950 | F3: ='Jira BUGS'!C3 | G3: ='Jira BUGS'!G3 | J3: 9 | K3: =COUNTIF($C$2:$C$1030,$J3) -> 5 | Q3: =COUNTIF($F$2:$F$1030,$P3) -> 914
A4: ='Jira BUGS'!A4 -> ESPC360-20940 | B4: =IFERROR(NETWORKDAYS('Jira BUGS'!D4,'Jira BUGS'!E4),0) -> 0 | C4: ='Jira BUGS'!O4 -> 9 | D4: ='Jira BUGS'!S4 -> 10 | E4: ='Jira BUGS'!J4 -> 45951 | F4: ='Jira BUGS'!C4 -> ERNESTO Gimeno Valiente | G4: ='Jira BUGS'!G4 | J4: 8 | K4: =COUNTIF($C$2:$C$1030,$J4) -> 4 | P4: GONZALO GARCIA MORENO | Q4: =COUNTIF($F$2:$F$1030,$P4) -> 2
A5: ='Jira BUGS'!A5 -> ESPC360-20658 | B5: =IFERROR(NETWORKDAYS('Jira BUGS'!D5,'Jira BUGS'!E5),0) -> 0 | C5: ='Jira BUGS'!O5 -> 9 | D5: ='Jira BUGS'!S5 -> 10 | E5: ='Jira BUGS'!J5 -> 45918 | F5: ='Jira BUGS'!C5 -> ERNESTO Gimeno Valiente | G5: ='Jira BUGS'!G5 | J5: 7 | K5: =COUNTIF($C$2:$C$1030,$J5) -> 6 | P5: BORJA CORTIJO LAJARA | Q5: =COUNTIF($F$2:$F$1030,$P5) -> 3
A6: ='Jira BUGS'!A6 -> ESPC360-20902 | B6: =IFERROR(NETWORKDAYS('Jira BUGS'!D6,'Jira BUGS'!E6),0) -> 0 | C6: ='Jira BUGS'!O6 -> 9 | D6: ='Jira BUGS'!S6 -> 9 | E6: ='Jira BUGS'!J6 -> 45917 | F6: ='Jira BUGS'!C6 -> ERNESTO Gimeno Valiente | G6: ='Jira BUGS'!G6 | J6: 6 | K6: =COUNTIF($C$2:$C$1030,$J6) -> 3 | P6: Andrei Brinza | Q6: =COUNTIF($F$2:$F$1030,$P6) -> 3
A7: ='Jira BUGS'!A7 -> ESPC360-20479 | B7: =IFERROR(NETWORKDAYS('Jira BUGS'!D7,'Jira BUGS'!E7),0) -> 0 | C7: ='Jira BUGS'!O7 -> 8 | D7: ='Jira BUGS'!S7 -> 9 | E7: ='Jira BUGS'!J7 -> 45912 | F7: ='Jira BUGS'!C7 -> ERNESTO Gimeno Valiente | G7: ='Jira BUGS'!G7 | J7: 5 | K7: =COUNTIF($C$2:$C$1030,$J7) -> 3 | P7: ERIC REVELLES SEGALES | Q7: =COUNTIF($F$2:$F$1030,$P7) -> 1
A8: ='Jira BUGS'!A8 -> ESPC360-20508 | B8: =IFERROR(NETWORKDAYS('Jira BUGS'!D8,'Jira BUGS'!E8),0) -> 0 | C8: ='Jira BUGS'!O8 -> 8 | D8: ='Jira BUGS'!S8 -> 9 | E8: ='Jira BUGS'!J8 -> 45901 | F8: ='Jira BUGS'!C8 -> GONZALO GARCIA MORENO | G8: ='Jira BUGS'!G8 | J8: 4 | K8: =COUNTIF($C$2:$C$1030,$J8) -> 7 | P8: JOSE FELIZ HERNANDEZ | Q8: =COUNTIF($F$2:$F$1030,$P8) -> 2
A9: ='Jira BUGS'!A9 -> ESPC360-19953 | B9: =IFERROR(NETWORKDAYS('Jira BUGS'!D9,'Jira BUGS'!E9),0) -> 0 | C9: ='Jira BUGS'!O9 -> 7 | D9: ='Jira BUGS'!S9 -> 9 | E9: ='Jira BUGS'!J9 -> 45862 | F9: ='Jira BUGS'!C9 -> BORJA CORTIJO LAJARA | G9: ='Jira BUGS'!G9 | J9: 3 | K9: =COUNTIF($C$2:$C$1030,$J9) -> 10 | P9: CARLOS Camacho Menchero | Q9: =COUNTIF($F$2:$F$1030,$P9) -> 8
A10: ='Jira BUGS'!A10 -> ESPC360-20269 | B10: =IFERROR(NETWORKDAYS('Jira BUGS'!D10,'Jira BUGS'!E10),0) -> 0 | C10: ='Jira BUGS'!O10 -> 8 | D10: ='Jira BUGS'!S10 -> 9 | E10: ='Jira BUGS'!J10 -> 45897 | F10: ='Jira BUGS'!C10 -> ERNESTO Gimeno Valiente | G10: ='Jira BUGS'!G10 | J10: 2 | K10: =COUNTIF($C$2:$C$1030,$J10) -> 10 | P10: Arturo Ruiz Simon | Q10: =COUNTIF($F$2:$F$1030,$P10) -> 1
A11: ='Jira BUGS'!A11 -> ESPC360-19956 | B11: =IFERROR(NETWORKDAYS('Jira BUGS'!D11,'Jira BUGS'!E11),0) -> 0 | C11: ='Jira BUGS'!O11 -> 7 | D11: ='Jira BUGS'!S11 -> 8 | E11: ='Jira BUGS'!J11 -> 45877 | F11: ='Jira BUGS'!C11 -> ERNESTO Gimeno Valiente | G11: ='Jira BUGS'!G11 | J11: 11 | K11: =COUNTIF($C$2:$C$1030,$J11) -> 3 | P11: 0 | Q11: =COUNTIF($F$2:$F$1030,$P11) -> 60
A12: ='Jira BUGS'!A12 -> ESPC360-20264 | B12: =IFERROR(NETWORKDAYS('Jira BUGS'!D12,'Jira BUGS'!E12),0) -> 0 | C12: ='Jira BUGS'!O12 -> 8 | D12: ='Jira BUGS'!S12 -> 8 | E12: ='Jira BUGS'!J12 -> 45876 | F12: ='Jira BUGS'!C12 -> ERNESTO Gimeno Valiente | G12: ='Jira BUGS'!G12 | J12: 1 | K12: =COUNTIF($C$2:$C$1030,$J12) -> 4 | P12: 0 | Q12: =COUNTIF($F$2:$F$1030,$P12) -> 60
A13: ='Jira BUGS'!A13 -> ESPC360-19693 | B13: =IFERROR(NETWORKDAYS('Jira BUGS'!D13,'Jira BUGS'!E13),0) -> 0 | C13: ='Jira BUGS'!O13 -> 7 | D13: ='Jira BUGS'!S13 -> 8 | E13: ='Jira BUGS'!J13 -> 45869 | F13: ='Jira BUGS'!C13 | G13: ='Jira BUGS'!G13 | J13: 12 | Q13: =COUNTIF($F$2:$F$1030,$P13) -> 60
A14: ='Jira BUGS'!A14 -> ESPC360-19944 | B14: =IFERROR(NETWORKDAYS('Jira BUGS'!D14,'Jira BUGS'!E14),0) -> 0 | C14: ='Jira BUGS'!O14 -> 7 | D14: ='Jira BUGS'!S14 -> 7 | E14: ='Jira BUGS'!J14 -> 45862 | F14: ='Jira BUGS'!C14 -> ERNESTO Gimeno Valiente | G14: ='Jira BUGS'!G14 | J14: 0 | Q14: =COUNTIF($F$2:$F$1030,$P14) -> 60
A15: ='Jira BUGS'!A15 -> ESPC360-19826 | B15: =IFERROR(NETWORKDAYS('Jira BUGS'!D15,'Jira BUGS'!E15),0) -> 0 | C15: ='Jira BUGS'!O15 -> 7 | D15: ='Jira BUGS'!S15 -> 7 | E15: ='Jira BUGS'!J15 -> 45861 | F15: ='Jira BUGS'!C15 -> ERNESTO Gimeno Valiente | G15: ='Jira BUGS'!G15 | Q15: =COUNTIF($F$2:$F$1030,$P15) -> 60
A16: ='Jira BUGS'!A16 -> ESPC360-19407 | B16: =IFERROR(NETWORKDAYS('Jira BUGS'!D16,'Jira BUGS'!E16),0) -> 0 | C16: ='Jira BUGS'!O16 -> 6 | D16: ='Jira BUGS'!S16 -> 7 | E16: ='Jira BUGS'!J16 -> 45855 | F16: ='Jira BUGS'!C16 -> ERNESTO Gimeno Valiente | G16: ='Jira BUGS'!G16 | J16: Media dias resolucion | K16: =ROUND(AVERAGE(B2:B1030),0) -> 0 | Q16: =COUNTIF($F$2:$F$1030,$P16) -> 60
A17: ='Jira BUGS'!A17 -> ESPC360-19755 | B17: =IFERROR(NETWORKDAYS('Jira BUGS'!D17,'Jira BUGS'!E17),0) -> 0 | C17: ='Jira BUGS'!O17 -> 7 | D17: ='Jira BUGS'!S17 -> 7 | E17: ='Jira BUGS'!J17 -> 45849 | F17: ='Jira BUGS'!C17 -> Andrei Brinza | G17: ='Jira BUGS'!G17 | Q17: =COUNTIF($F$2:$F$1030,$P17) -> 60
A18: ='Jira BUGS'!A18 -> ESPC360-19490 | B18: =IFERROR(NETWORKDAYS('Jira BUGS'!D18,'Jira BUGS'!E18),0) -> 0 | C18: ='Jira BUGS'!O18 -> 6 | D18: ='Jira BUGS'!S18 -> 7 | E18: ='Jira BUGS'!J18 -> 45835 | F18: ='Jira BUGS'!C18 -> ERNESTO Gimeno Valiente | G18: ='Jira BUGS'!G18 | Q18: =COUNTIF($F$2:$F$1030,$P18) -> 60
A19: ='Jira BUGS'!A19 -> ESPC360-19162 | B19: =IFERROR(NETWORKDAYS('Jira BUGS'!D19,'Jira BUGS'!E19),0) -> 0 | C19: ='Jira BUGS'!O19 -> 6 | D19: ='Jira BUGS'!S19 -> 7 | E19: ='Jira BUGS'!J19 -> 45835 | F19: ='Jira BUGS'!C19 -> ERNESTO Gimeno Valiente | G19: ='Jira BUGS'!G19 | J19: Media dias resolucion mes | Q19: =COUNTIF($F$2:$F$1030,$P19) -> 60
A20: ='Jira BUGS'!A20 -> ESPC360-18907 | B20: =IFERROR(NETWORKDAYS('Jira BUGS'!D20,'Jira BUGS'!E20),0) -> 0 | C20: ='Jira BUGS'!O20 -> 5 | D20: ='Jira BUGS'!S20 -> 6 | E20: ='Jira BUGS'!J20 -> 45821 | F20: ='Jira BUGS'!C20 -> ERNESTO Gimeno Valiente | G20: ='Jira BUGS'!G20 | J20: Mes | K20: total apariciones | L20: suma apariciones | M20: media mensual | Q20: =COUNTIF($F$2:$F$1030,$P20) -> 60
A21: ='Jira BUGS'!A21 -> ESPC360-18427 | B21: =IFERROR(NETWORKDAYS('Jira BUGS'!D21,'Jira BUGS'!E21),0) -> 0 | C21: ='Jira BUGS'!O21 -> 5 | D21: ='Jira BUGS'!S21 -> 6 | E21: ='Jira BUGS'!J21 -> 45813 | F21: ='Jira BUGS'!C21 -> ERNESTO Gimeno Valiente | G21: ='Jira BUGS'!G21 | J21: {=_xlfn.UNIQUE($D$2:$D$122)} -> 10 | K21: =COUNTIF($D$2:$D$5030,$J21) -> 4 | L21: =SUMIF($D$2:$D$5030,$J21,$B$2:$B$5030) -> 0 | M21: =ROUND(L21/K21,0) -> 0 | Q21: =COUNTIF($F$2:$F$1030,$P21) -> 60
A22: ='Jira BUGS'!A22 -> ESPC360-18426 | B22: =IFERROR(NETWORKDAYS('Jira BUGS'!D22,'Jira BUGS'!E22),0) -> 0 | C22: ='Jira BUGS'!O22 -> 5 | D22: ='Jira BUGS'!S22 -> 6 | E22: ='Jira BUGS'!J22 | F22: ='Jira BUGS'!C22 -> ERNESTO Gimeno Valiente | G22: ='Jira BUGS'!G22 | J22: 9 | K22: =COUNTIF($D$2:$D$5030,$J22) -> 5 | L22: =SUMIF($D$2:$D$5030,$J22,$B$2:$B$5030) -> 0 | M22: =ROUND(L22/K22,0) -> 0 | Q22: =COUNTIF($F$2:$F$1030,$P22) -> 60
A23: ='Jira BUGS'!A23 -> ESPC360-18050 | B23: =IFERROR(NETWORKDAYS('Jira BUGS'!D23,'Jira BUGS'!E23),0) -> 0 | C23: ='Jira BUGS'!O23 -> 4 | D23: ='Jira BUGS'!S23 -> 6 | E23: ='Jira BUGS'!J23 | F23: ='Jira BUGS'!C23 | G23: ='Jira BUGS'!G23 | J23: 8 | K23: =COUNTIF($D$2:$D$5030,$J23) -> 3 | L23: =SUMIF($D$2:$D$5030,$J23,$B$2:$B$5030) -> 0 | M23: =ROUND(L23/K23,0) -> 0 | Q23: =COUNTIF($F$2:$F$1030,$P23) -> 60
A24: ='Jira BUGS'!A24 -> ESPC360-17357 | B24: =IFERROR(NETWORKDAYS('Jira BUGS'!D24,'Jira BUGS'!E24),0) -> 0 | C24: ='Jira BUGS'!O24 -> 4 | D24: ='Jira BUGS'!S24 -> 6 | E24: ='Jira BUGS'!J24 -> 45751 | F24: ='Jira BUGS'!C24 -> Andrei Brinza | G24: ='Jira BUGS'!G24 | J24: 7 | K24: =COUNTIF($D$2:$D$5030,$J24) -> 6 | L24: =SUMIF($D$2:$D$5030,$J24,$B$2:$B$5030) -> 0 | M24: =ROUND(L24/K24,0) -> 0 | Q24: =COUNTIF($F$2:$F$1030,$P24) -> 60
A25: ='Jira BUGS'!A25 -> ESPC360-17664 | B25: =IFERROR(NETWORKDAYS('Jira BUGS'!D25,'Jira BUGS'!E25),0) -> 0 | C25: ='Jira BUGS'!O25 -> 4 | D25: ='Jira BUGS'!S25 -> 6 | E25: ='Jira BUGS'!J25 -> 45758 | F25: ='Jira BUGS'!C25 -> Andrei Brinza | G25: ='Jira BUGS'!G25 | J25: 6 | K25: =COUNTIF($D$2:$D$5030,$J25) -> 6 | L25: =SUMIF($D$2:$D$5030,$J25,$B$2:$B$5030) -> 0 | M25: =ROUND(L25/K25,0) -> 0 | Q25: =COUNTIF($F$2:$F$1030,$P25) -> 60
A26: ='Jira BUGS'!A26 -> ESPC360-17189 | B26: =IFERROR(NETWORKDAYS('Jira BUGS'!D26,'Jira BUGS'!E26),0) -> 0 | C26: ='Jira BUGS'!O26 -> 3 | D26: ='Jira BUGS'!S26 -> 5 | E26: ='Jira BUGS'!J26 -> 45743 | F26: ='Jira BUGS'!C26 -> ERIC REVELLES SEGALES | G26: ='Jira BUGS'!G26 | J26: 5 | K26: =COUNTIF($D$2:$D$5030,$J26) -> 7 | L26: =SUMIF($D$2:$D$5030,$J26,$B$2:$B$5030) -> 0 | M26: =ROUND(L26/K26,0) -> 0 | Q26: =COUNTIF($F$2:$F$1030,$P26) -> 60
A27: ='Jira BUGS'!A27 -> ESPC360-17713 | B27: =IFERROR(NETWORKDAYS('Jira BUGS'!D27,'Jira BUGS'!E27),0) -> 0 | C27: ='Jira BUGS'!O27 -> 4 | D27: ='Jira BUGS'!S27 -> 5 | E27: ='Jira BUGS'!J27 -> 45779 | F27: ='Jira BUGS'!C27 -> ERNESTO Gimeno Valiente | G27: ='Jira BUGS'!G27 | J27: 4 | K27: =COUNTIF($D$2:$D$5030,$J27) -> 5 | L27: =SUMIF($D$2:$D$5030,$J27,$B$2:$B$5030) -> 0 | M27: =ROUND(L27/K27,0) -> 0 | Q27: =COUNTIF($F$2:$F$1030,$P27) -> 60
A28: ='Jira BUGS'!A28 -> ESPC360-16743 | B28: =IFERROR(NETWORKDAYS('Jira BUGS'!D28,'Jira BUGS'!E28),0) -> 0 | C28: ='Jira BUGS'!O28 -> 3 | D28: ='Jira BUGS'!S28 -> 5 | E28: ='Jira BUGS'!J28 -> 45727 | F28: ='Jira BUGS'!C28 -> BORJA CORTIJO LAJARA | G28: ='Jira BUGS'!G28 | J28: 3 | K28: =COUNTIF($D$2:$D$5030,$J28) -> 10 | L28: =SUMIF($D$2:$D$5030,$J28,$B$2:$B$5030) -> 0 | M28: =ROUND(L28/K28,0) -> 0 | Q28: =COUNTIF($F$2:$F$1030,$P28) -> 60
A29: ='Jira BUGS'!A29 -> ESPC360-17055 | B29: =IFERROR(NETWORKDAYS('Jira BUGS'!D29,'Jira BUGS'!E29),0) -> 0 | C29: ='Jira BUGS'!O29 -> 3 | D29: ='Jira BUGS'!S29 -> 5 | E29: ='Jira BUGS'!J29 -> 45751 | F29: ='Jira BUGS'!C29 | G29: ='Jira BUGS'!G29 | J29: 2 | K29: =COUNTIF($D$2:$D$5030,$J29) -> 7 | L29: =SUMIF($D$2:$D$5030,$J29,$B$2:$B$5030) -> 0 | M29: =ROUND(L29/K29,0) -> 0 | Q29: =COUNTIF($F$2:$F$1030,$P29) -> 60
A30: ='Jira BUGS'!A30 -> ESPC360-18044 | B30: =IFERROR(NETWORKDAYS('Jira BUGS'!D30,'Jira BUGS'!E30),0) -> 0 | C30: ='Jira BUGS'!O30 -> 4 | D30: ='Jira BUGS'!S30 -> 5 | E30: ='Jira BUGS'!J30 | F30: ='Jira BUGS'!C30 -> ERNESTO Gimeno Valiente | G30: ='Jira BUGS'!G30 | J30: 1 | K30: =COUNTIF($D$2:$D$5030,$J30) -> 8 | L30: =SUMIF($D$2:$D$5030,$J30,$B$2:$B$5030) -> 0 | M30: =ROUND(L30/K30,0) -> 0 | Q30: =COUNTIF($F$2:$F$1030,$P30) -> 60
A31: ='Jira BUGS'!A31 -> ESPC360-17446 | B31: =IFERROR(NETWORKDAYS('Jira BUGS'!D31,'Jira BUGS'!E31),0) -> 0 | C31: ='Jira BUGS'!O31 -> 4 | D31: ='Jira BUGS'!S31 -> 5 | E31: ='Jira BUGS'!J31 -> 45769 | F31: ='Jira BUGS'!C31 -> ERNESTO Gimeno Valiente | G31: ='Jira BUGS'!G31 | J31: 0 | K31: =COUNTIF($D$2:$D$5030,$J31) -> 60 | L31: =SUMIF($D$2:$D$5030,$J31,$B$2:$B$5030) -> 0 | M31: =ROUND(L31/K31,0) -> 0 | Q31: =COUNTIF($F$2:$F$1030,$P31) -> 60
A32: ='Jira BUGS'!A32 -> ESPC360-17380 | B32: =IFERROR(NETWORKDAYS('Jira BUGS'!D32,'Jira BUGS'!E32),0) -> 0 | C32: ='Jira BUGS'!O32 -> 4 | D32: ='Jira BUGS'!S32 -> 5 | E32: ='Jira BUGS'!J32 -> 45782 | F32: ='Jira BUGS'!C32 -> ERNESTO Gimeno Valiente | G32: ='Jira BUGS'!G32 | Q32: =COUNTIF($F$2:$F$1030,$P32) -> 60
